Workbook

Sheet D_Tier_Full_List
A1: D-TIER: 1,760 items | 1,457 Never Consumed | 244 Slow Movers | 13 Have ROP in LN
A2: item_code | B2: item_description | C2: item_group | D2: item_group_label | E2: planning_signal | F2: standard_cost_usd | G2: total_lbs_all_years | H2: lbs_2021_2023 | I2: lbs_2024_2025 | J2: last_year_consumed | K2: has_rop_in_ln | L2: d_tier_reason
A3: 0263CLER | B3: No description on file | C3: 8003 | D3: Raw Materials (8003) | E3: RMI | F3: 1.455 | G3: 0 | H3: 0 | I3: 0 | J3: Never | K3: NO — no ROP set in LN | L3: NEVER CONSUMED — set up in LN but never used. Strong candidate for deactivation.
A4: 0263CLER_TEST | B4: No description on file | C4: 8003 | D4: Raw Materials (8003) | E4: OBS | F4: 0 | G4: 0 | H4: 0 | I4: 0 | J4: Never | K4: NO — no ROP set in LN | L4: NEVER CONSUMED — set up in LN but never used. Strong candidate for deactivation.
A5: 0263DEEP | B5: No description on file | C5: 8003 | D5: Raw Materials (8003) | E5: RMI | F5: 1.436 | G5: 0 | H5: 0 | I5: 0 | J5: Never | K5: NO — no ROP set in LN | L5: NEVER CONSUMED — set up in LN but never used. Strong candidate for deactivation.
A6: 0263WITE | B6: No description on file | C6: 8003 | D6: Raw Materials (8003) | E6: RMI | F6: 1.426 | G6: 0 | H6: 0 | I6: 0 | J6: Never | K6: NO — no ROP set in LN | L6: NEVER CONSUMED — set up in LN but never used. Strong candidate for deactivation.
A7: 081DR716A | B7: No description on file | C7: 8003 | D7: Raw Materials (8003) | E7: RMI | F7: 3.1185 | G7: 0 | H7: 0 | I7: 0 | J7: Never | K7: NO — no ROP set in LN | L7: NEVER CONSUMED — set up in LN but never used. Strong candidate for deactivation.
A8: 084D0725A | B8: No description on file | C8: 8003 | D8: Raw Materials (8003) | E8: RMD | F8: 2.4802 | G8: 0 | H8: 0 | I8: 0 | J8: Never | K8: NO — no ROP set in LN | L8: NEVER CONSUMED — set up in LN but never used. Strong candidate for deactivation.
A9: 084D0766A | B9: No description on file | C9: 8003 | D9: Raw Materials (8003) | E9: RMI | F9: 2.5486 | G9: 0 | H9: 0 | I9: 0 | J9: Never | K9: NO — no ROP set in LN | L9: NEVER CONSUMED — set up in LN but never used. Strong candidate for deactivation.
A10: 084D0900A | B10: No description on file | C10: 8003 | D10: Raw Materials (8003) | E10: RMD | F10: 2.676 | G10: 0 | H10: 0 | I10: 0 | J10: Never | K10: NO — no ROP set in LN | L10: NEVER CONSUMED — set up in LN but never used. Strong candidate for deactivation.
A11: 084DF748A | B11: No description on file | C11: 8003 | D11: Raw Materials (8003) | E11: RMD | F11: 2.7419 | G11: 0 | H11: 0 | I11: 0 | J11: Never | K11: NO — no ROP set in LN | L11: NEVER CONSUMED — set up in LN but never used. Strong candidate for deactivation.
A12: 085D02000 | B12: No description on file | C12: 8003 | D12: Raw Materials (8003) | E12: RMI | F12: 0.71 | G12: 0 | H12: 0 | I12: 0 | J12: Never | K12: NO — no ROP set in LN | L12: NEVER CONSUMED — set up in LN but never used. Strong candidate for deactivation.
A13: 086D00000 | B13: No description on file | C13: 8003 | D13: Raw Materials (8003) | E13: RMI | F13: 7.6035 | G13: 0 | H13: 0 | I13: 0 | J13: Never | K13: NO — no ROP set in LN | L13: NEVER CONSUMED — set up in LN but never used. Strong candidate for deactivation.
A14: 089D02000 | B14: No description on file | C14: 8003 | D14: Raw Materials (8003) | E14: RMI | F14: 0.63 | G14: 0 | H14: 0 | I14: 0 | J14: Never | K14: NO — no ROP set in LN | L14: NEVER CONSUMED — set up in LN but never used. Strong candidate for deactivation.
... A1459: X-005 | B1459: No description on file | C1459: 8010 | D1459: Packaging (8010) | E1459: NOT SET | F1459: 0 | G1459: 0 | H1459: 0 | I1459: 0 | J1459: Never | K1459: NO — no ROP set in LN | L1459: NEVER CONSUMED — set up in LN but never used. Strong candidate for deactivation.
A1460: CS112 | B1460: Stabilizer | C1460: 8003 | D1460: Raw Materials (8003) | E1460: NOT SET | F1460: 8.77 | G1460: 0.03 | H1460: 0 | I1460: 0 | J1460: 2026 | K1460: NO — no ROP set in LN | L1460: ZERO RECENT CONSUMPTION — verify with Pat
A1461: CM1206 | B1461: Defoamer (Silicone) | C1461: 8003 | D1461: Raw Materials (8003) | E1461: RMI | F1461: 29 | G1461: 0.0713 | H1461: 0.0713 | I1461: 0 | J1461: 2022 | K1461: NO — no ROP set in LN | L1461: SLOW MOVER — consumed in 2021-2023 (last: 2022), then dropped to zero. Check if reformulated or discontinued.
A1462: H274 | B1462: Additive - Thickener | C1462: 8003 | D1462: Raw Materials (8003) | E1462: NOT SET | F1462: 3.34 | G1462: 0.47 | H1462: 0 | I1462: 0 | J1462: 2026 | K1462: NO — no ROP set in LN | L1462: ZERO RECENT CONSUMPTION — verify with Pat
A1463: CM1061 | B1463: Toluhydroquinone | C1463: 8003 | D1463: Raw Materials (8003) | E1463: RMI | F1463: 111.65 | G1463: 0.49 | H1463: 0.49 | I1463: 0 | J1463: 2022 | K1463: NO — no ROP set in LN | L1463: SLOW MOVER — consumed in 2021-2023 (last: 2022), then dropped to zero. Check if reformulated or discontinued.
A1464: PCC6097 | B1464: Yellow Epoxy Dispersion | C1464: 8003 | D1464: Raw Materials (8003) | E1464: NOT SET | F1464: 13.62 | G1464: 0.91 | H1464: 0 | I1464: 0 | J1464: 2026 | K1464: YES — ROP set, consider zeroing out | L1464: ZERO RECENT CONSUMPTION — verify with Pat
A1465: W87F | B1465: Zinc Oxide | C1465: 8003 | D1465: Raw Materials (8003) | E1465: RMI | F1465: 2.68 | G1465: 0.95 | H1465: 0.95 | I1465: 0 | J1465: 2023 | K1465: NO — no ROP set in LN | L1465: SLOW MOVER — consumed in 2021-2023 (last: 2023), then dropped to zero. Check if reformulated or discontinued.
A1466: PAYD5035 | B1466: Tint-Ayd CW 5611 (Red Paste) | C1466: 8003 | D1466: Raw Materials (8003) | E1466: NOT SET | F1466: 5.278 | G1466: 1.1 | H1466: 0 | I1466: 0 | J1466: 2026 | K1466: NO — no ROP set in LN | L1466: ZERO RECENT CONSUMPTION — verify with Pat
A1467: CM1059 | B1467: Phenothiazine | C1467: 8003 | D1467: Raw Materials (8003) | E1467: RMI | F1467: 43.264 | G1467: 1.2 | H1467: 1.2 | I1467: 0 | J1467: 2022 | K1467: NO — no ROP set in LN | L1467: SLOW MOVER — consumed in 2021-2023 (last: 2022), then dropped to zero. Check if reformulated or discontinued.
A1468: PVOC1015 | B1468: 0-VOC Blue Dispersion | C1468: 8003 | D1468: Raw Materials (8003) | E1468: NOT SET | F1468: 11.42 | G1468: 1.29 | H1468: 1.29 | I1468: 0 | J1468: 2022 | K1468: NO — no ROP set in LN | L1468: SLOW MOVER — consumed in 2021-2023 (last: 2022), then dropped to zero. Check if reformulated or discontinued.
A1469: CM951 | B1469: Fatty Amine Surfactant | C1469: 8003 | D1469: Raw Materials (8003) | E1469: RMI | F1469: 5.42 | G1469: 1.49 | H1469: 1.49 | I1469: 0 | J1469: 2021 | K1469: NO — no ROP set in LN | L1469: SLOW MOVER — consumed in 2021-2023 (last: 2021), then dropped to zero. Check if reformulated or discontinued.
A1470: CM569 | B1470: Additive - Anti-Microbial | C1470: 8003 | D1470: Raw Materials (8003) | E1470: RMI | F1470: 54.15 | G1470: 1.56 | H1470: 1.56 | I1470: 0 | J1470: 2021 | K1470: NO — no ROP set in LN | L1470: SLOW MOVER — consumed in 2021-2023 (last: 2021), then dropped to zero. Check if reformulated or discontinued.
A1471: CM1065 | B1471: Additive-Defoamer | C1471: 8003 | D1471: Raw Materials (8003) | E1471: RMI | F1471: 5.718 | G1471: 1.95 | H1471: 1.95 | I1471: 0 | J1471: 2021 | K1471: NO — no ROP set in LN | L1471: SLOW MOVER — consumed in 2021-2023 (last: 2021), then dropped to zero. Check if reformulated or discontinued.
... A1762: H439F | B1762: Cement | C1762: 8003 | D1762: Raw Materials (8003) | E1762: RMU | F1762: 0.0715 | G1762: 2699531.4 | H1762: 2699531.4 | I1762: 0 | J1762: 2022 | K1762: NO — no ROP set in LN | L1762: SLOW MOVER — consumed in 2021-2023 (last: 2022), then dropped to zero. Check if reformulated or discontinued.

Sheet Site_Summary
A1: CARBOLINE MASTER SUMMARY v4 | All 4 Sites | OTD=78.0% (2-day tol.) | Good Apple/Bad Apple + Bulk Tank Caps Applied
A2: v4 NEW: 94 Bad Apples have SS=0 | 59 Good Apples using manager lead times | 6 LC items tank-capped | GB tank caps defined (RS977/T25/RS554/T10 not yet in ROP file)
A4: Site | B4: Items | C4: 🔴 A-Underst. | D4: ⭐ GoodApple Underst. | E4: 🗑 BadApple In File | F4: New SS($) | G4: New ROP($) | H4: Avg Inv($) | I4: Avg LT(d) | J4: OTD% | K4: Notes
A5: Lake Charles | B5: 280 | C5: 36 | D5: 0 | E5: 13 | F5: 7755044 | G5: 14167422 | H5: 10961233 | I5: 38.6 | J5: 72.4 | K5: 280 items. 6 tank-capped items. RS977 capped at 103,057LB.
A6: Green Bay | B6: 549 | C6: 31 | D6: 26 | E6: 57 | F6: 3892171.5 | G6: 7604062.9 | H6: 5748117.2 | I6: 32.3 | J6: 68.8 | K6: 549 items. 4 GB tanks not in ROP yet (Pat must add RS977/T25/RS554/T10).
A7: Dayton | B7: 348 | C7: 38 | D7: 7 | E7: 24 | F7: 3320822.2 | G7: 6216995 | H7: 4768908.6 | I7: 40.4 | J7: 68.8 | K7: 348 items. Dillon temp through Aug.
A8: Louisa | B8: 30 | C8: 7 | D8: 0 | E8: 0 | F8: 738144.07 | G8: 1425102.1 | H8: 1081623.1 | I8: 57.4 | J8: 68.9 | K8: 30 raw material items. 7 A-items all understocked.
A9: ALL SITES TOTAL | B9: 1207 | C9: 112 | D9: 33 | E9: 94 | F9: 15706182 | G9: 29413582 | H9: 22559882 | I9: 36.7 | J9: 69.6 | K9: All 4 sites. v4 = most complete calculation to date.

Sheet Master_Data
A1: MASTER DATA v4 | 1,789 rows | Cols S-X = Excel formulas | Good Apple/Bad Apple + Tank Caps
A2: A-R = raw data | S=ss$ (=G×M) T=rop$ (=H×M) U=avg_inv$ (=(G+H)/2×M) V=curr_rop$ (=F×M) W=days_curr (=F/L) X=days_rec (=H/L) | Col G=new_ss uses manager lead time for Good Apples, 0 for Bad Apples
A4: site_group | B4: item_code | C4: item_description | D4: abc_tier | E4: audit_flag_v4 | F4: is_good_apple | G4: is_bad_apple | H4: current_rop_in_ln | I4: new_ss_lbs_v4 | J4: new_rop_lbs_v4 | K4: rop_to_enter_ln | L4: avg_lead_time_days | M4: otd_pct_2day | N4: avg_daily_usage_lbs | O4: standard_cost_usd | P4: rop_gap_lbs_v4 | Q4: rop_gap_direction_v4 | R4: lt_source_v4 | S4: buffer_factor_v4 | T4: moq_order_increment | U4: ss_dollars ▶F=I×O | V4: rop_dollars ▶F=J×O | W4: avg_inv_$ ▶F=(I+J)/2×O | X4: curr_rop_$ ▶F=H×O
A5: Lake Charles | B5: AP30 | C5: Plasticizer | D5: B | E5: 🔵 REVIEW — Overstocked | F5: NO | G5: NO | H5: 26219 | I5: 11334.47 | J5: 22668.94 | K5: 43938 | L5: 31.1 | M5: 81.2 | N5: 364.45238 | O5: 2.831 | P5: 3550.06 | Q5: OVERSTOCKED — excess cash | R5: From PO history | S5: 1 | T5: 43938 | U5: =I5*O5 -> 32087.885 | V5: =J5*O5 -> 64175.769 | W5: =((I5+J5)/2)*O5 -> 48131.827 | X5: =H5*O5 -> 74225.989
A6: Lake Charles | B6: B16 | C6: Black Pigment | D6: C | E6: 🟠 MONITOR — C-item understocked | F6: NO | G6: NO | H6: 588 | I6: 253.88 | J6: 761.64 | K6: 882 | L6: 24.9 | M6: 69 | N6: 20.392096 | O6: 5.944 | P6: -173.64 | Q6: UNDERSTOCKED — stockout risk | R6: From PO history | S6: 0.5 | T6: 441 | U6: =I6*O6 -> 1509.0627 | V6: =J6*O6 -> 4527.1882 | W6: =((I6+J6)/2)*O6 -> 3018.1254 | X6: =H6*O6 -> 3495.072
A7: Lake Charles | B7: B52 | C7: Black Pigment | D7: C | E7: 🟠 MONITOR — C-item understocked | F7: NO | G7: NO | H7: 1396 | I7: 783.39 | J7: 2350.17 | K7: 3968 | L7: 35.7 | M7: 50.8 | N7: 43.887411 | O7: 3.77 | P7: -954.17 | Q7: UNDERSTOCKED — stockout risk | R7: From PO history | S7: 0.5 | T7: 1984 | U7: =I7*O7 -> 2953.3803 | V7: =J7*O7 -> 8860.1409 | W7: =((I7+J7)/2)*O7 -> 5906.7606 | X7: =H7*O7 -> 5262.92
A8: Lake Charles | B8: B67 | C8: Black Pigment | D8: C | E8: 🟠 MONITOR — C-item understocked | F8: NO | G8: NO | H8: 256 | I8: 149.68 | J8: 449.04 | K8: 881.92 | L8: 32.2 | M8: 84.6 | N8: 9.296973 | O8: 2.416 | P8: -193.04 | Q8: UNDERSTOCKED — stockout risk | R8: From PO history | S8: 0.5 | T8: 440.96 | U8: =I8*O8 -> 361.62688 | V8: =J8*O8 -> 1084.8806 | W8: =((I8+J8)/2)*O8 -> 723.25376 | X8: =H8*O8 -> 618.496
A9: Lake Charles | B9: B86 | C9: Black Pigment | D9: C | E9: 🟠 MONITOR — C-item understocked | F9: NO | G9: NO | H9: 988 | I9: 873.97 | J9: 2621.91 | K9: 5000 | L9: 46.9 | M9: 59.1 | N9: 37.269603 | O9: 1.76 | P9: -1633.91 | Q9: UNDERSTOCKED — stockout risk | R9: From PO history | S9: 0.5 | T9: 2500 | U9: =I9*O9 -> 1538.1872 | V9: =J9*O9 -> 4614.5616 | W9: =((I9+J9)/2)*O9 -> 3076.3744 | X9: =H9*O9 -> 1738.88
A10: Lake Charles | B10: C0003U | C10: Std 1-qt can, not lined | D10: A | E10: 🔴 TOP PRIORITY — A-item understocked | F10: NO | G10: NO | H10: 3356 | I10: 6283.72 | J10: 10472.86 | K10: 15360 | L10: 59.9 | M10: 54.5 | N10: 69.935616 | O10: 0.942 | P10: -7116.86 | Q10: UNDERSTOCKED — stockout risk | R10: From PO history | S10: 1.5 | T10: 7680 | U10: =I10*O10 -> 5919.2642 | V10: =J10*O10 -> 9865.4341 | W10: =((I10+J10)/2)*O10 -> 7892.3492 | X10: =H10*O10 -> 3161.352
A11: Lake Charles | B11: C01LNCAN | C11: Gallon can, tall, lined | D11: B | E11: 🟡 REVIEW — B-item understocked | F11: NO | G11: NO | H11: 498 | I11: 524.68 | J11: 1049.36 | K11: 2160 | L11: 48.6 | M11: 76 | N11: 10.79589 | O11: 2.02 | P11: -551.36 | Q11: UNDERSTOCKED — stockout risk | R11: From PO history | S11: 1 | T11: 2160 | U11: =I11*O11 -> 1059.8536 | V11: =J11*O11 -> 2119.7072 | W11: =((I11+J11)/2)*O11 -> 1589.7804 | X11: =H11*O11 -> 1005.96
A12: Lake Charles | B12: C01PBLK | C12: 1 gal black plastic pail | D12: B | E12: 🟡 REVIEW — B-item understocked | F12: NO | G12: NO | H12: 4210 | I12: 2396.23 | J12: 4792.46 | K12: 6720 | L12: 29 | M12: 72.5 | N12: 82.628767 | O12: 2.5 | P12: -582.46 | Q12: UNDERSTOCKED — stockout risk | R12: From PO history | S12: 1 | T12: 3360 | U12: =I12*O12 -> 5990.575 | V12: =J12*O12 -> 11981.15 | W12: =((I12+J12)/2)*O12 -> 8985.8625 | X12: =H12*O12 -> 10525
A13: Lake Charles | B13: C01PMPLUG | C13: Lined plug for C01PBLK | D13: B | E13: 🟡 REVIEW — B-item understocked | F13: NO | G13: NO | H13: 4208 | I13: 2305.49 | J13: 4610.98 | K13: 6720 | L13: 28.2 | M13: 69.8 | N13: 81.754795 | O13: 1.13 | P13: -402.98 | Q13: UNDERSTOCKED — stockout risk | R13: From PO history | S13: 1 | T13: 3360 | U13: =I13*O13 -> 2605.2037 | V13: =J13*O13 -> 5210.4074 | W13: =((I13+J13)/2)*O13 -> 3907.8056 | X13: =H13*O13 -> 4755.04
A14: Lake Charles | B14: C01U | C14: Gal can, tall, unlined w/beads | D14: A | E14: 🔴 TOP PRIORITY — A-item understocked | F14: NO | G14: NO | H14: 28000 | I14: 99867.81 | J14: 166446.35 | K14: 169344 | L14: 64.8 | M14: 77.8 | N14: 1027.4466 | O14: 1.56 | P14: -138446.35 | Q14: UNDERSTOCKED — stockout risk | R14: From PO history | S14: 1.5 | T14: 14112 | U14: =I14*O14 -> 155793.78 | V14: =J14*O14 -> 259656.31 | W14: =((I14+J14)/2)*O14 -> 207725.04 | X14: =H14*O14 -> 43680
A15: Lake Charles | B15: C01UGSKP | C15: Unlined gasketed plug | D15: C | E15: 🔵 REVIEW — Overstocked | F15: NO | G15: NO | H15: 2921 | I15: 843.09 | J15: 2529.27 | K15: 3600 | L15: 35.3 | M15: 42.9 | N15: 47.767123 | O15: 0.6784 | P15: 391.73 | Q15: OVERSTOCKED — excess cash | R15: From PO history | S15: 0.5 | T15: 3600 | U15: =I15*O15 -> 571.95226 | V15: =J15*O15 -> 1715.8568 | W15: =((I15+J15)/2)*O15 -> 1143.9045 | X15: =H15*O15 -> 1981.6064
A16: Lake Charles | B16: C01UPLUG | C16: Unlined plug for 1 gal tall | D16: A | E16: 🔴 TOP PRIORITY — A-item understocked | F16: NO | G16: NO | H16: 28000 | I16: 97303.79 | J16: 162172.98 | K16: 165600 | L16: 66.3 | M16: 78.9 | N16: 978.41918 | O16: 0.34 | P16: -134172.98 | Q16: UNDERSTOCKED — stockout risk | R16: From PO history | S16: 1.5 | T16: 7200 | U16: =I16*O16 -> 33083.289 | V16: =J16*O16 -> 55138.813 | W16: =((I16+J16)/2)*O16 -> 44111.051 | X16: =H16*O16 -> 9520
... A284: Lake Charles | B284: Z86 | C284: Aluminum Powder, Dedusted | D284: B | E284: 🟡 REVIEW — B-item understocked | F284: NO | G284: NO | H284: 5668 | I284: 6000 | J284: 13616.91 | K284: 19200 | L284: 36.2 | M284: 74.6 | N284: 210.41184 | O284: 6.77 | P284: -7948.91 | Q284: UNDERSTOCKED — stockout risk | R284: From PO history | BULK TANK CAPPED at 6, | S284: 1 | T284: 6400 | U284: =I284*O284 -> 40620 | V284: =J284*O284 -> 92186.481 | W284: =((I284+J284)/2)*O284 -> 66403.24 | X284: =H284*O284 -> 38372.36
A285: Green Bay | B285: 01650909B01D | C285: Bitumastic 300 M Part B 0909 | D285: OUT_OF_SCOPE | E285: Out of scope | F285: NO | G285: NO | H285: 376 | I285: 0 | J285: 0 | K285: 0 | L285: 26.1 | N285: 1.683562 | O285: 0 | P285: 376 | Q285: OVERSTOCKED — excess cash | R285: OUT_OF_SCOPE — finished good | S285: 0 | T285: 36 | U285: =I285*O285 -> 0 | V285: =J285*O285 -> 0 | W285: =((I285+J285)/2)*O285 -> 0 | X285: =H285*O285 -> 0
A286: Green Bay | B286: 01650909B1QD | C286: Bitumastic 300 M Part B 0909 | D286: OUT_OF_SCOPE | E286: Out of scope | F286: NO | G286: NO | H286: 48 | I286: 0 | J286: 0 | K286: 0 | L286: 26.1 | N286: 0.339726 | O286: 0 | P286: 48 | Q286: OVERSTOCKED — excess cash | R286: OUT_OF_SCOPE — finished good | S286: 0 | T286: 8 | U286: =I286*O286 -> 0 | V286: =J286*O286 -> 0 | W286: =((I286+J286)/2)*O286 -> 0 | X286: =H286*O286 -> 0
A287: Green Bay | B287: 0165P900A01D | C287: Bitumastic 300 M Part A Black | D287: OUT_OF_SCOPE | E287: Out of scope | F287: NO | G287: NO | H287: 32 | I287: 0 | J287: 0 | K287: 0 | L287: 58.3 | M287: 100 | N287: 0.435616 | O287: 0 | P287: 32 | Q287: OVERSTOCKED — excess cash | R287: OUT_OF_SCOPE — finished good | S287: 0 | T287: 8 | U287: =I287*O287 -> 0 | V287: =J287*O287 -> 0 | W287: =((I287+J287)/2)*O287 -> 0 | X287: =H287*O287 -> 0
A288: Green Bay | B288: 0165P900A04D | C288: Bitumastic 300 M Part A Black | D288: OUT_OF_SCOPE | E288: Out of scope | F288: NO | G288: NO | H288: 132 | I288: 0 | J288: 0 | K288: 0 | L288: 39.7 | M288: 97.9 | N288: 1.09863 | O288: 0 | P288: 132 | Q288: OVERSTOCKED — excess cash | R288: OUT_OF_SCOPE — finished good | S288: 0 | T288: 36 | U288: =I288*O288 -> 0 | V288: =J288*O288 -> 0 | W288: =((I288+J288)/2)*O288 -> 0 | X288: =H288*O288 -> 0
A289: Green Bay | B289: 01850908B01D | C289: Carbomastic 15 Part B 0908 | D289: OUT_OF_SCOPE | E289: Out of scope | F289: NO | G289: NO | H289: 24 | I289: 0 | J289: 0 | K289: 0 | L289: 26.1 | N289: 0.432877 | O289: 0 | P289: 24 | Q289: OVERSTOCKED — excess cash | R289: OUT_OF_SCOPE — finished good | S289: 0 | T289: 8 | U289: =I289*O289 -> 0 | V289: =J289*O289 -> 0 | W289: =((I289+J289)/2)*O289 -> 0 | X289: =H289*O289 -> 0
A290: Green Bay | B290: 01850908B05D | C290: Carbomastic 15 Part B 0908 | D290: OUT_OF_SCOPE | E290: Out of scope | F290: NO | G290: NO | H290: 16 | I290: 0 | J290: 0 | K290: 0 | L290: 26.1 | N290: 0.150685 | O290: 0 | P290: 16 | Q290: OVERSTOCKED — excess cash | R290: OUT_OF_SCOPE — finished good | S290: 0 | T290: 4 | U290: =I290*O290 -> 0 | V290: =J290*O290 -> 0 | W290: =((I290+J290)/2)*O290 -> 0 | X290: =H290*O290 -> 0
A291: Green Bay | B291: 0185C901A01D | C291: Carbomastic 15 Part A Aluminum | D291: OUT_OF_SCOPE | E291: Out of scope | F291: NO | G291: NO | H291: 24 | I291: 0 | J291: 0 | K291: 0 | L291: 26.1 | N291: 0.435616 | O291: 0 | P291: 24 | Q291: OVERSTOCKED — excess cash | R291: OUT_OF_SCOPE — finished good | S291: 0 | T291: 8 | U291: =I291*O291 -> 0 | V291: =J291*O291 -> 0 | W291: =((I291+J291)/2)*O291 -> 0 | X291: =H291*O291 -> 0
A292: Green Bay | B292: 0185C901A05D | C292: Carbomastic 15 Part A Aluminum | D292: OUT_OF_SCOPE | E292: Out of scope | F292: NO | G292: NO | H292: 8 | I292: 0 | J292: 0 | K292: 0 | L292: 26.1 | N292: 0.150685 | O292: 0 | P292: 8 | Q292: OVERSTOCKED — excess cash | R292: OUT_OF_SCOPE — finished good | S292: 0 | T292: 4 | U292: =I292*O292 -> 0 | V292: =J292*O292 -> 0 | W292: =((I292+J292)/2)*O292 -> 0 | X292: =H292*O292 -> 0
A293: Green Bay | B293: 0185M500A01D | C293: Carbomastic 15 Part A Red M500 | D293: OUT_OF_SCOPE | E293: Out of scope | F293: NO | G293: NO | H293: 8 | I293: 0 | J293: 0 | K293: 0 | L293: 26.1 | N293: 0.121918 | O293: 0 | P293: 8 | Q293: OVERSTOCKED — excess cash | R293: OUT_OF_SCOPE — finished good | S293: 0 | T293: 4 | U293: =I293*O293 -> 0 | V293: =J293*O293 -> 0 | W293: =((I293+J293)/2)*O293 -> 0 | X293: =H293*O293 -> 0
A294: Green Bay | B294: 0185M500A05D | C294: Carbomastic 15 Part A Red M500 | D294: OUT_OF_SCOPE | E294: Out of scope | F294: NO | G294: NO | H294: 2 | I294: 0 | J294: 0 | K294: 0 | L294: 26.1 | N294: 0.034247 | O294: 0 | P294: 2 | Q294: OVERSTOCKED — excess cash | R294: OUT_OF_SCOPE — finished good | S294: 0 | T294: 2 | U294: =I294*O294 -> 0 | V294: =J294*O294 -> 0 | W294: =((I294+J294)/2)*O294 -> 0 | X294: =H294*O294 -> 0
A295: Green Bay | B295: 01860908B01D | C295: Carbomastic 15 FC Part B 0908 | D295: OUT_OF_SCOPE | E295: Out of scope | F295: NO | G295: NO | H295: 16 | I295: 0 | J295: 0 | K295: 0 | L295: 26.1 | N295: 0.180822 | O295: 0 | P295: 16 | Q295: OVERSTOCKED — excess cash | R295: OUT_OF_SCOPE — finished good | S295: 0 | T295: 3 | U295: =I295*O295 -> 0 | V295: =J295*O295 -> 0 | W295: =((I295+J295)/2)*O295 -> 0 | X295: =H295*O295 -> 0
A296: Green Bay | B296: 01860908B05D | C296: Carbomastic 15 FC Part B 0908 | D296: OUT_OF_SCOPE | E296: Out of scope | F296: NO | G296: NO | H296: 6 | I296: 0 | J296: 0 | K296: 0 | L296: 26.1 | N296: 0.045205 | O296: 0 | P296: 6 | Q296: OVERSTOCKED — excess cash | R296: OUT_OF_SCOPE — finished good | S296: 0 | T296: 3 | U296: =I296*O296 -> 0 | V296: =J296*O296 -> 0 | W296: =((I296+J296)/2)*O296 -> 0 | X296: =H296*O296 -> 0
A297: Green Bay | B297: 01951803A01D | C297: Carbothane 133 LV Part A White | D297: OUT_OF_SCOPE | E297: Out of scope | F297: NO | G297: NO | H297: 8 | I297: 0 | J297: 0 | K297: 0 | L297: 26.1 | N297: 0.083562 | O297: 0 | P297: 8 | Q297: OVERSTOCKED — excess cash | R297: OUT_OF_SCOPE — finished good | S297: 0 | T297: 1 | U297: =I297*O297 -> 0 | V297: =J297*O297 -> 0 | W297: =((I297+J297)/2)*O297 -> 0 | X297: =H297*O297 -> 0
A298: Green Bay | B298: 01951803A04D | C298: Carbothane 133 LV Part A White | D298: OUT_OF_SCOPE | E298: Out of scope | F298: NO | G298: NO | H298: 8 | I298: 0 | J298: 0 | K298: 0 | L298: 26.1 | N298: 0.141096 | O298: 0 | P298: 8 | Q298: OVERSTOCKED — excess cash | R298: OUT_OF_SCOPE — finished good | S298: 0 | T298: 1 | U298: =I298*O298 -> 0 | V298: =J298*O298 -> 0 | W298: =((I298+J298)/2)*O298 -> 0 | X298: =H298*O298 -> 0
A299: Green Bay | B299: 01951864A04D | C299: Carbothane 133 LV Part A White | D299: OUT_OF_SCOPE | E299: Out of scope | F299: NO | G299: NO | H299: 4 | I299: 0 | J299: 0 | K299: 0 | L299: 26.1 | N299: 0.039726 | O299: 0 | P299: 4 | Q299: OVERSTOCKED — excess cash | R299: OUT_OF_SCOPE — finished good | S299: 0 | T299: 1 | U299: =I299*O299 -> 0 | V299: =J299*O299 -> 0 | W299: =((I299+J299)/2)*O299 -> 0 | X299: =H299*O299 -> 0
A300: Green Bay | B300: 0195CLERAGWD | C300: Carbothane 133 LV Part A CLER | D300: OUT_OF_SCOPE | E300: Out of scope | F300: NO | G300: NO | H300: 96 | I300: 0 | J300: 0 | K300: 0 | L300: 26.1 | N300: 1.59726 | O300: 0 | P300: 96 | Q300: OVERSTOCKED — excess cash | R300: OUT_OF_SCOPE — finished good | S300: 0 | T300: 1 | U300: =I300*O300 -> 0 | V300: =J300*O300 -> 0 | W300: =((I300+J300)/2)*O300 -> 0 | X300: =H300*O300 -> 0
... A304: Green Bay | B304: 0195WITEATND | C304: Carbothane 133 LV Part A WITE | D304: OUT_OF_SCOPE | E304: Out of scope | F304: NO | G304: NO | H304: 96 | I304: 0 | J304: 0 | K304: 0 | L304: 26.1 | N304: 1.158904 | O304: 0 | P304: 96 | Q304: OVERSTOCKED — excess cash | R304: OUT_OF_SCOPE — finished good | S304: 0 | T304: 1 | U304: =I304*O304 -> 0 | V304: =J304*O304 -> 0 | W304: =((I304+J304)/2)*O304 -> 0 | X304: =H304*O304 -> 0
A305: Green Bay | B305: 02290904BZ1D | C305: Zinc Filler Type II | D305: OUT_OF_SCOPE | E305: Out of scope | F305: NO | G305: NO | H305: 376 | I305: 0 | J305: 0 | K305: 0 | L305: 55.3 | M305: 97.9 | N305: 5.835616 | O305: 0 | P305: 376 | Q305: OVERSTOCKED — excess cash | R305: OUT_OF_SCOPE — finished good | S305: 0 | T305: 1 | U305: =I305*O305 -> 0 | V305: =J305*O305 -> 0 | W305: =((I305+J305)/2)*O305 -> 0 | X305: =H305*O305 -> 0
A306: Green Bay | B306: 02290904BZ2D | C306: Zinc Filler Type II | D306: OUT_OF_SCOPE | E306: Out of scope | F306: NO | G306: NO | H306: 316 | I306: 0 | J306: 0 | K306: 0 | L306: 83.6 | M306: 97.7 | N306: 5.047945 | O306: 0 | P306: 316 | Q306: OVERSTOCKED — excess cash | R306: OUT_OF_SCOPE — finished good | S306: 0 | T306: 1 | U306: =I306*O306 -> 0 | V306: =J306*O306 -> 0 | W306: =((I306+J306)/2)*O306 -> 0 | X306: =H306*O306 -> 0
A307: Green Bay | B307: 02490300A2ED | C307: Carbozinc 11 HS Base Green 030 | D307: OUT_OF_SCOPE | E307: Out of scope | F307: NO | G307: NO | H307: 120 | I307: 0 | J307: 0 | K307: 0 | L307: 26.1 | N307: 1.238356 | O307: 0 | P307: 120 | Q307: OVERSTOCKED — excess cash | R307: OUT_OF_SCOPE — finished good | S307: 0 | T307: 8 | U307: =I307*O307 -> 0 | V307: =J307*O307 -> 0 | W307: =((I307+J307)/2)*O307 -> 0 | X307: =H307*O307 -> 0
A308: Green Bay | B308: 02490300A4UD | C308: Carbozinc 11 HS Base Green 030 | D308: OUT_OF_SCOPE | E308: Out of scope | F308: NO | G308: NO | H308: 36 | I308: 0 | J308: 0 | K308: 0 | L308: 26.1 | N308: 0.609589 | O308: 0 | P308: 36 | Q308: OVERSTOCKED — excess cash | R308: OUT_OF_SCOPE — finished good | S308: 0 | T308: 8 | U308: =I308*O308 -> 0 | V308: =J308*O308 -> 0 | W308: =((I308+J308)/2)*O308 -> 0 | X308: =H308*O308 -> 0
A309: Green Bay | B309: 02490700A2ED | C309: Carbozinc 11 HS Base Grey 0700 | D309: OUT_OF_SCOPE | E309: Out of scope | F309: NO | G309: NO | H309: 24 | I309: 0 | J309: 0 | K309: 0 | L309: 26.1 | N309: 0.20411 | O309: 0 | P309: 24 | Q309: OVERSTOCKED — excess cash | R309: OUT_OF_SCOPE — finished good | S309: 0 | T309: 3 | U309: =I309*O309 -> 0 | V309: =J309*O309 -> 0 | W309: =((I309+J309)/2)*O309 -> 0 | X309: =H309*O309 -> 0
A310: Green Bay | B310: 02490700A4UD | C310: Carbozinc 11 HS Base Grey 0700 | D310: OUT_OF_SCOPE | E310: Out of scope | F310: NO | G310: NO | H310: 36 | I310: 0 | J310: 0 | K310: 0 | L310: 26.1 | N310: 0.764384 | O310: 0 | P310: 36 | Q310: OVERSTOCKED — excess cash | R310: OUT_OF_SCOPE — finished good | S310: 0 | T310: 12 | U310: =I310*O310 -> 0 | V310: =J310*O310 -> 0 | W310: =((I310+J310)/2)*O310 -> 0 | X310: =H310*O310 -> 0
A311: Green Bay | B311: 02490910C1QD | C311: Carbozinc HS Activator | D311: OUT_OF_SCOPE | E311: Out of scope | F311: NO | G311: NO | H311: 112 | I311: 0 | J311: 0 | K311: 0 | L311: 17.2 | M311: 98 | N311: 1.6 | O311: 0 | P311: 112 | Q311: OVERSTOCKED — excess cash | R311: OUT_OF_SCOPE — finished good | S311: 0 | T311: 12 | U311: =I311*O311 -> 0 | V311: =J311*O311 -> 0 | W311: =((I311+J311)/2)*O311 -> 0 | X311: =H311*O311 -> 0
...

Sheet Out_Of_Scope_Explained
A1: OUT OF SCOPE (582) — Finished goods — NOT 8003/8010 raw materials
A2: item_code | B2: item_description | C2: product_type | D2: product_type_label | E2: site_group | F2: current_rop_in_ln
A3: 01650909B01D | B3: Bitumastic 300 M Part B 0909 | C3: TSA | D3: Thermally Sprayed Aluminum | E3: Green Bay | F3: 376
A4: 01650909B1QD | B4: Bitumastic 300 M Part B 0909 | C4: TSA | D4: Thermally Sprayed Aluminum | E4: Green Bay | F4: 48
A5: 0165P900A01D | B5: Bitumastic 300 M Part A Black | C5: TSA | D5: Thermally Sprayed Aluminum | E5: Green Bay | F5: 32
A6: 0165P900A04D | B6: Bitumastic 300 M Part A Black | C6: TSA | D6: Thermally Sprayed Aluminum | E6: Green Bay | F6: 132
A7: 01850908B01D | B7: Carbomastic 15 Part B 0908 | C7: TSA | D7: Thermally Sprayed Aluminum | E7: Green Bay | F7: 24
A8: 01850908B05D | B8: Carbomastic 15 Part B 0908 | C8: TSA | D8: Thermally Sprayed Aluminum | E8: Green Bay | F8: 16
A9: 0185C901A01D | B9: Carbomastic 15 Part A Aluminum | C9: TSA | D9: Thermally Sprayed Aluminum | E9: Green Bay | F9: 24
A10: 0185C901A05D | B10: Carbomastic 15 Part A Aluminum | C10: TSA | D10: Thermally Sprayed Aluminum | E10: Green Bay | F10: 8
A11: 0185M500A01D | B11: Carbomastic 15 Part A Red M500 | C11: TSA | D11: Thermally Sprayed Aluminum | E11: Green Bay | F11: 8
A12: 0185M500A05D | B12: Carbomastic 15 Part A Red M500 | C12: TSA | D12: Thermally Sprayed Aluminum | E12: Green Bay | F12: 2
A13: 01860908B01D | B13: Carbomastic 15 FC Part B 0908 | C13: KMM | D13: Knockdown/Mix Material | E13: Green Bay | F13: 16
A14: 01860908B05D | B14: Carbomastic 15 FC Part B 0908 | C14: KMM | D14: Knockdown/Mix Material | E14: Green Bay | F14: 6
... A584: STRCHWRP | B584: Stretch Wrap 80 Gauge | C584: TSA | D584: Thermally Sprayed Aluminum | E584: Green Bay | F584: 160

Sheet ABC_by_Site
A1: ABC BY SITE | Cols K-L = SUMPRODUCT formulas from Master_Data | v4 (Bad Apples excluded from totals)
A2: site | B2: tier | C2: count | D2: underst. | E2: overst. | F2: ok | G2: ss_lbs | H2: rop_lbs | I2: avg_lt | J2: avg_otd | K2: ss_$ ▶F | L2: rop_$ ▶F
A3: Lake Charles | B3: A | C3: 37 | D3: 36 | E3: 1 | F3: 0 | G3: 3240713.9 | H3: 5623762.3 | I3: 48 | J3: 75.8 | K3: =SUMPRODUCT((Master_Data!$A$5:$A$1793="Lake Charles")*(Master_Data!$D$5:$D$1793="A")*(Master_Data!$G$5:$G$1793="NO")*Master_Data!$U$5:$U$1793) -> 6033453.2 | L3: =SUMPRODUCT((Master_Data!$A$5:$A$1793="Lake Charles")*(Master_Data!$D$5:$D$1793="A")*(Master_Data!$G$5:$G$1793="NO")*Master_Data!$V$5:$V$1793) -> 10418770
A4: Lake Charles | B4: B | C4: 76 | D4: 69 | E4: 7 | F4: 0 | G4: 546456.21 | H4: 1094529.3 | I4: 38.3 | J4: 73.5 | K4: =SUMPRODUCT((Master_Data!$A$5:$A$1793="Lake Charles")*(Master_Data!$D$5:$D$1793="B")*(Master_Data!$G$5:$G$1793="NO")*Master_Data!$U$5:$U$1793) -> 1427066.5 | L4: =SUMPRODUCT((Master_Data!$A$5:$A$1793="Lake Charles")*(Master_Data!$D$5:$D$1793="B")*(Master_Data!$G$5:$G$1793="NO")*Master_Data!$V$5:$V$1793) -> 2865079.5
A5: Lake Charles | B5: C | C5: 150 | D5: 84 | E5: 65 | F5: 1 | G5: 56217.18 | H5: 168651.51 | I5: 37.1 | J5: 71.5 | K5: =SUMPRODUCT((Master_Data!$A$5:$A$1793="Lake Charles")*(Master_Data!$D$5:$D$1793="C")*(Master_Data!$G$5:$G$1793="NO")*Master_Data!$U$5:$U$1793) -> 294524.2 | L5: =SUMPRODUCT((Master_Data!$A$5:$A$1793="Lake Charles")*(Master_Data!$D$5:$D$1793="C")*(Master_Data!$G$5:$G$1793="NO")*Master_Data!$V$5:$V$1793) -> 883572.05
A6: Lake Charles | B6: D | C6: 4 | D6: 0 | E6: 4 | F6: 0 | G6: 0 | H6: 0 | I6: 36.8 | J6: 85.1 | K6: =SUMPRODUCT((Master_Data!$A$5:$A$1793="Lake Charles")*(Master_Data!$D$5:$D$1793="D")*(Master_Data!$G$5:$G$1793="NO")*Master_Data!$U$5:$U$1793) -> 0 | L6: =SUMPRODUCT((Master_Data!$A$5:$A$1793="Lake Charles")*(Master_Data!$D$5:$D$1793="D")*(Master_Data!$G$5:$G$1793="NO")*Master_Data!$V$5:$V$1793) -> 0
A7: Lake Charles SUBTOTAL | K7: =SUMPRODUCT((Master_Data!$A$5:$A$1793="Lake Charles")*(Master_Data!$D$5:$D$1793<>"OUT_OF_SCOPE")*(Master_Data!$G$5:$G$1793="NO")*Master_Data!$U$5:$U$1793) -> 7755044 | L7: =SUMPRODUCT((Master_Data!$A$5:$A$1793="Lake Charles")*(Master_Data!$D$5:$D$1793<>"OUT_OF_SCOPE")*(Master_Data!$G$5:$G$1793="NO")*Master_Data!$V$5:$V$1793) -> 14167422
A9: Green Bay | B9: A | C9: 31 | D9: 31 | E9: 0 | F9: 0 | G9: 1258834.2 | H9: 2098057 | I9: 44.9 | J9: 75.3 | K9: =SUMPRODUCT((Master_Data!$A$5:$A$1793="Green Bay")*(Master_Data!$D$5:$D$1793="A")*(Master_Data!$G$5:$G$1793="NO")*Master_Data!$U$5:$U$1793) -> 1783181.2 | L9: =SUMPRODUCT((Master_Data!$A$5:$A$1793="Green Bay")*(Master_Data!$D$5:$D$1793="A")*(Master_Data!$G$5:$G$1793="NO")*Master_Data!$V$5:$V$1793) -> 2971968.6
A10: Green Bay | B10: B | C10: 102 | D10: 98 | E10: 4 | F10: 0 | G10: 630005.97 | H10: 1260011.9 | I10: 36.4 | J10: 73.9 | K10: =SUMPRODUCT((Master_Data!$A$5:$A$1793="Green Bay")*(Master_Data!$D$5:$D$1793="B")*(Master_Data!$G$5:$G$1793="NO")*Master_Data!$U$5:$U$1793) -> 1694878.7 | L10: =SUMPRODUCT((Master_Data!$A$5:$A$1793="Green Bay")*(Master_Data!$D$5:$D$1793="B")*(Master_Data!$G$5:$G$1793="NO")*Master_Data!$V$5:$V$1793) -> 3389757.5
A11: Green Bay | B11: C | C11: 348 | D11: 230 | E11: 118 | F11: 0 | G11: 91943.09 | H11: 275829.51 | I11: 31 | J11: 67.2 | K11: =SUMPRODUCT((Master_Data!$A$5:$A$1793="Green Bay")*(Master_Data!$D$5:$D$1793="C")*(Master_Data!$G$5:$G$1793="NO")*Master_Data!$U$5:$U$1793) -> 414111.56 | L11: =SUMPRODUCT((Master_Data!$A$5:$A$1793="Green Bay")*(Master_Data!$D$5:$D$1793="C")*(Master_Data!$G$5:$G$1793="NO")*Master_Data!$V$5:$V$1793) -> 1242336.8
A12: Green Bay | B12: D | C12: 11 | D12: 0 | E12: 11 | F12: 0 | G12: 0 | H12: 0 | I12: 46.5 | J12: 70.1 | K12: =SUMPRODUCT((Master_Data!$A$5:$A$1793="Green Bay")*(Master_Data!$D$5:$D$1793="D")*(Master_Data!$G$5:$G$1793="NO")*Master_Data!$U$5:$U$1793) -> 0 | L12: =SUMPRODUCT((Master_Data!$A$5:$A$1793="Green Bay")*(Master_Data!$D$5:$D$1793="D")*(Master_Data!$G$5:$G$1793="NO")*Master_Data!$V$5:$V$1793) -> 0
A13: Green Bay SUBTOTAL | K13: =SUMPRODUCT((Master_Data!$A$5:$A$1793="Green Bay")*(Master_Data!$D$5:$D$1793<>"OUT_OF_SCOPE")*(Master_Data!$G$5:$G$1793="NO")*Master_Data!$U$5:$U$1793) -> 3892171.5 | L13: =SUMPRODUCT((Master_Data!$A$5:$A$1793="Green Bay")*(Master_Data!$D$5:$D$1793<>"OUT_OF_SCOPE")*(Master_Data!$G$5:$G$1793="NO")*Master_Data!$V$5:$V$1793) -> 7604062.9
A15: Dayton | B15: A | C15: 39 | D15: 38 | E15: 1 | F15: 0 | G15: 1178739.5 | H15: 1964565.9 | I15: 52.6 | J15: 72.7 | K15: =SUMPRODUCT((Master_Data!$A$5:$A$1793="Dayton")*(Master_Data!$D$5:$D$1793="A")*(Master_Data!$G$5:$G$1793="NO")*Master_Data!$U$5:$U$1793) -> 2075857.9 | L15: =SUMPRODUCT((Master_Data!$A$5:$A$1793="Dayton")*(Master_Data!$D$5:$D$1793="A")*(Master_Data!$G$5:$G$1793="NO")*Master_Data!$V$5:$V$1793) -> 3459763.2
A16: Dayton | B16: B | C16: 84 | D16: 76 | E16: 8 | F16: 0 | G16: 358744.81 | H16: 717489.62 | I16: 43.7 | J16: 69.4 | K16: =SUMPRODUCT((Master_Data!$A$5:$A$1793="Dayton")*(Master_Data!$D$5:$D$1793="B")*(Master_Data!$G$5:$G$1793="NO")*Master_Data!$U$5:$U$1793) -> 977661.52 | L16: =SUMPRODUCT((Master_Data!$A$5:$A$1793="Dayton")*(Master_Data!$D$5:$D$1793="B")*(Master_Data!$G$5:$G$1793="NO")*Master_Data!$V$5:$V$1793) -> 1955323
A17: Dayton | B17: C | C17: 201 | D17: 91 | E17: 110 | F17: 0 | G17: 57766.86 | H17: 173300.67 | I17: 37.2 | J17: 67.9 | K17: =SUMPRODUCT((Master_Data!$A$5:$A$1793="Dayton")*(Master_Data!$D$5:$D$1793="C")*(Master_Data!$G$5:$G$1793="NO")*Master_Data!$U$5:$U$1793) -> 267302.79 | L17: =SUMPRODUCT((Master_Data!$A$5:$A$1793="Dayton")*(Master_Data!$D$5:$D$1793="C")*(Master_Data!$G$5:$G$1793="NO")*Master_Data!$V$5:$V$1793) -> 801908.7
A18: Dayton SUBTOTAL | K18: =SUMPRODUCT((Master_Data!$A$5:$A$1793="Dayton")*(Master_Data!$D$5:$D$1793<>"OUT_OF_SCOPE")*(Master_Data!$G$5:$G$1793="NO")*Master_Data!$U$5:$U$1793) -> 3320822.2 | L18: =SUMPRODUCT((Master_Data!$A$5:$A$1793="Dayton")*(Master_Data!$D$5:$D$1793<>"OUT_OF_SCOPE")*(Master_Data!$G$5:$G$1793="NO")*Master_Data!$V$5:$V$1793) -> 6216995
A20: Louisa | B20: A | C20: 7 | D20: 7 | E20: 0 | F20: 0 | G20: 1925613.7 | H20: 3209356.1 | I20: 48.2 | J20: 71.8 | K20: =SUMPRODUCT((Master_Data!$A$5:$A$1793="Louisa")*(Master_Data!$D$5:$D$1793="A")*(Master_Data!$G$5:$G$1793="NO")*Master_Data!$U$5:$U$1793) -> 381468.47 | L20: =SUMPRODUCT((Master_Data!$A$5:$A$1793="Louisa")*(Master_Data!$D$5:$D$1793="A")*(Master_Data!$G$5:$G$1793="NO")*Master_Data!$V$5:$V$1793) -> 635780.77
A21: Louisa | B21: B | C21: 7 | D21: 7 | E21: 0 | F21: 0 | G21: 140506.33 | H21: 281012.66 | I21: 64.1 | J21: 81.9 | K21: =SUMPRODUCT((Master_Data!$A$5:$A$1793="Louisa")*(Master_Data!$D$5:$D$1793="B")*(Master_Data!$G$5:$G$1793="NO")*Master_Data!$U$5:$U$1793) -> 280705.72 | L21: =SUMPRODUCT((Master_Data!$A$5:$A$1793="Louisa")*(Master_Data!$D$5:$D$1793="B")*(Master_Data!$G$5:$G$1793="NO")*Master_Data!$V$5:$V$1793) -> 561411.43
A22: Louisa | B22: C | C22: 16 | D22: 15 | E22: 1 | F22: 0 | G22: 27888.01 | H22: 83664.08 | I22: 58.4 | J22: 62 | K22: =SUMPRODUCT((Master_Data!$A$5:$A$1793="Louisa")*(Master_Data!$D$5:$D$1793="C")*(Master_Data!$G$5:$G$1793="NO")*Master_Data!$U$5:$U$1793) -> 75969.883 | L22: =SUMPRODUCT((Master_Data!$A$5:$A$1793="Louisa")*(Master_Data!$D$5:$D$1793="C")*(Master_Data!$G$5:$G$1793="NO")*Master_Data!$V$5:$V$1793) -> 227909.91
A23: Louisa SUBTOTAL | K23: =SUMPRODUCT((Master_Data!$A$5:$A$1793="Louisa")*(Master_Data!$D$5:$D$1793<>"OUT_OF_SCOPE")*(Master_Data!$G$5:$G$1793="NO")*Master_Data!$U$5:$U$1793) -> 738144.07 | L23: =SUMPRODUCT((Master_Data!$A$5:$A$1793="Louisa")*(Master_Data!$D$5:$D$1793<>"OUT_OF_SCOPE")*(Master_Data!$G$5:$G$1793="NO")*Master_Data!$V$5:$V$1793) -> 1425102.1

Sheet Action_Items
A1: ACTION ITEMS — v4 Update | June 23-24 2026
A2: ID | B2: Details | C2: Owner
A3: 1 ✅ GOOD APPLE FLAGS | B3: 59 Good Apple items in ROP file now use manager-provided lead times. SS calculated with manager's lead time instead of avg PO history. 33 Good Apple items are understocked. 26 are stocked OK. 93 Good Apples are NOT in the ROP file — Pat must add LN ordering params for these. | C3: Done ✅ | Pat: add 93 items
A4: 2 ✅ BAD APPLE FLAGS | B4: 94 Bad Apple items in ROP file now have SS=0 and priority_score=0. They will never appear in the Priority Audit List. Pat should remove their ordering parameters in LN item ordering session. 1,056 Bad Apples already have no ROP set in LN — correct as-is. 1 duplicate (RS1100) removed from source file. | C4: Done ✅ | Pat: remove 94 items
A5: 3 ✅ LC BULK TANK CAPS | B5: 6 Lake Charles items capped at 80% of tank max: RS977 (103,057LB), RS820 (71,432LB), RS825 (72,000LB), CM1115 (95,933LB), CM847 (51,478LB), Z86 (6,000LB hard safety cap). Uncapped values stored in lt_source_v4 column for reference. | C5: Done ✅
A6: 4 ✅ GB BULK TANK CAPS DEFINED | B6: GB caps: RS977=36,000LB | T25=32,000LB | RS554=35,200LB | T10=12,800LB. Formula: 80% × (max_capacity − must_be_down_to). These 4 items are NOT in the ROP file yet — Pat needs to add LN ordering params first. | C6: Done ✅ defined | Pat: add 4 GB tank items
A7: 5 🔴 PAT: 93 GOOD APPLE ITEMS NEED LN PARAMS | B7: 93 Good Apple items are on manager's always-stock list but have NO ordering parameters set in LN. Without ROP in LN, the system will not generate planned orders. See ⭐ Good_Apple_Missing_ROP sheet in SS file for the full list. | C7: Pat — this week
A8: 6 🔴 PAT: 4 GB TANK ITEMS NEED LN PARAMS | B8: RS977, T25, RS554, T10 at Green Bay have no ROP in LN. These are bulk liquid raw materials that need active ordering parameters. | C8: Pat — this week
A9: 7 🔴 LOUISA URGENT | B9: H350F, H419F, H450F at Louisa: LN ROP is 35K-50K LB but should be 240K-917K LB. Pat must update immediately. | C9: Pat — URGENT
A10: 8 ⚠ MORE GOOD APPLES COMING | B10: Manager said this is the first cut of Good Apples (~146 items). Better/fuller list coming. When it arrives, re-run v4 Python script to update flags. | C10: Manager — pending
